Workbook

Sheet Historical Data
B1: CANADIAN PERISHABLE COMMODITY PRICE HISTORY (2022–2024)
B2: Monthly wholesale prices (CAD $/tonne) – Sources: AAFC Market Information Service; Statistics Canada
B4: Month / Year | C4: Tomatoes (CAD$/t) | D4: Peppers (CAD$/t) | E4: Lettuce (CAD$/t) | F4: CPI Index | G4: Fuel Index | H4: Notes
B5: Jan-2022 | C5: 820 | D5: 1380 | E5: 510 | F5: 100 | G5: 100 | H5: Base period
B6: Feb-2022 | C6: 835 | D6: 1410 | E6: 490 | F6: 100.6 | G6: 102.1
B7: Mar-2022 | C7: 870 | D7: 1450 | E7: 530 | F7: 101.2 | G7: 108.4 | H7: Ukraine conflict – fuel spike
B8: Apr-2022 | C8: 910 | D8: 1490 | E8: 560 | F8: 102 | G8: 115.2 | H8: Spring planting season
B9: May-2022 | C9: 960 | D9: 1540 | E9: 580 | F9: 102.8 | G9: 118.6 | H9: Early field season begins
B10: Jun-2022 | C10: 1020 | D10: 1620 | E10: 610 | F10: 103.5 | G10: 121.3 | H10: Peak demand – BBQ season
B11: Jul-2022 | C11: 1050 | D11: 1680 | E11: 590 | F11: 104.1 | G11: 122.8 | H11: Peak harvest – Ontario field tomatoes
B12: Aug-2022 | C12: 1030 | D12: 1650 | E12: 570 | F12: 104.3 | G12: 119.4 | H12: Abundant supply – price softens
B13: Sep-2022 | C13: 990 | D13: 1600 | E13: 550 | F13: 104.6 | G13: 114.2 | H13: Late harvest
B14: Oct-2022 | C14: 940 | D14: 1540 | E14: 530 | F14: 105 | G14: 110.8 | H14: Season wind-down
B15: Nov-2022 | C15: 880 | D15: 1480 | E15: 500 | F15: 105.4 | G15: 107.3 | H15: Greenhouse dominates supply
B16: Dec-2022 | C16: 850 | D16: 1430 | E16: 480 | F16: 105.8 | G16: 104.1 | H16: Holiday demand boost
B17: Jan-2023 | C17: 855 | D17: 1440 | E17: 495 | F17: 106.3 | G17: 101.8 | H17: New year – supply tight
B18: Feb-2023 | C18: 870 | D18: 1460 | E18: 505 | F18: 106.9 | G18: 103.2
B19: Mar-2023 | C19: 900 | D19: 1490 | E19: 535 | F19: 107.5 | G19: 106.8
B20: Apr-2023 | C20: 945 | D20: 1530 | E20: 565 | F20: 108.2 | G20: 109.4
B21: May-2023 | C21: 985 | D21: 1570 | E21: 590 | F21: 108.8 | G21: 111.2 | H21: Dry spring – lower yields forecast
B22: Jun-2023 | C22: 1040 | D22: 1640 | E22: 625 | F22: 109.4 | G22: 113.8 | H22: Strong foodservice demand
B23: Jul-2023 | C23: 1075 | D23: 1700 | E23: 608 | F23: 109.9 | G23: 115.1 | H23: Heat dome – Ontario July 2023
B24: Aug-2023 | C24: 1055 | D24: 1670 | E24: 585 | F24: 110.2 | G24: 113.6
B25: Sep-2023 | C25: 1010 | D25: 1620 | E25: 558 | F25: 110.6 | G25: 110.9
B26: Oct-2023 | C26: 958 | D26: 1555 | E26: 534 | F26: 111 | G26: 108.4
B27: Nov-2023 | C27: 905 | D27: 1495 | E27: 508 | F27: 111.5 | G27: 105.8
B28: Dec-2023 | C28: 875 | D28: 1448 | E28: 488 | F28: 111.9 | G28: 103.5
B29: Jan-2024 | C29: 888 | D29: 1462 | E29: 502 | F29: 112.5 | G29: 102.4
B30: Feb-2024 | C30: 902 | D30: 1478 | E30: 515 | F30: 113.1 | G30: 104.8
B31: Mar-2024 | C31: 932 | D31: 1512 | E31: 542 | F31: 113.8 | G31: 107.6
B32: Apr-2024 | C32: 968 | D32: 1558 | E32: 572 | F32: 114.5 | G32: 110.3
B33: May-2024 | C33: 1008 | D33: 1598 | E33: 598 | F33: 115.2 | G33: 112.8 | H33: Labour cost increases
B34: Jun-2024 | C34: 1062 | D34: 1662 | E34: 630 | F34: 115.8 | G34: 115.4 | H34: Strong retail demand
B35: Jul-2024 | C35: 1088 | D35: 1718 | E35: 615 | F35: 116.3 | G35: 116.9 | H35: Record greenhouse output
B36: Aug-2024 | C36: 1068 | D36: 1685 | E36: 592 | F36: 116.7 | G36: 114.8
B37: Sep-2024 | C37: 1022 | D37: 1632 | E37: 564 | F37: 117.1 | G37: 112.1
B38: Oct-2024 | C38: 972 | D38: 1568 | E38: 540 | F38: 117.5 | G38: 109.6
B39: Nov-2024 | C39: 918 | D39: 1505 | E39: 512 | F39: 117.9 | G39: 106.9
B40: Dec-2024 | C40: 888 | D40: 1458 | E40: 492 | F40: 118.4 | G40: 104.5 | H40: Year-end inventory clearance
B42: SUMMARY STATISTICS (2022–2024)
...

Sheet Price Analysis
B1: PRICE ANALYSIS – MOVING AVERAGES, SEASONALITY & YEAR-ON-YEAR CHANGE
B2: Statistical analysis of tomato prices. Extend to peppers/lettuce by changing the source column reference.
B4: Month | C4: Actual Price (CAD$/t) | D4: 3-Month MA (CAD$/t) | E4: 6-Month MA (CAD$/t) | F4: 12-Month MA (CAD$/t) | G4: MoM Change % | H4: YoY Change % | I4: Seasonal Index | J4: Price Band Low | K4: Price Band High
B5: Jan-2022 | C5: ='Historical Data'!C5 -> 820
B6: Feb-2022 | C6: ='Historical Data'!C6 -> 835 | G6: =IFERROR((C6-C5)/C5,0) -> 0.018292683
B7: Mar-2022 | C7: ='Historical Data'!C7 -> 870 | D7: =AVERAGE(C5:C7) -> 841.66667 | G7: =IFERROR((C7-C6)/C6,0) -> 0.041916168
B8: Apr-2022 | C8: ='Historical Data'!C8 -> 910 | D8: =AVERAGE(C6:C8) -> 871.66667 | G8: =IFERROR((C8-C7)/C7,0) -> 0.045977011
B9: May-2022 | C9: ='Historical Data'!C9 -> 960 | D9: =AVERAGE(C7:C9) -> 913.33333 | G9: =IFERROR((C9-C8)/C8,0) -> 0.054945055
B10: Jun-2022 | C10: ='Historical Data'!C10 -> 1020 | D10: =AVERAGE(C8:C10) -> 963.33333 | E10: =AVERAGE(C5:C10) -> 902.5 | G10: =IFERROR((C10-C9)/C9,0) -> 0.0625
B11: Jul-2022 | C11: ='Historical Data'!C11 -> 1050 | D11: =AVERAGE(C9:C11) -> 1010 | E11: =AVERAGE(C6:C11) -> 940.83333 | G11: =IFERROR((C11-C10)/C10,0) -> 0.029411765
B12: Aug-2022 | C12: ='Historical Data'!C12 -> 1030 | D12: =AVERAGE(C10:C12) -> 1033.3333 | E12: =AVERAGE(C7:C12) -> 973.33333 | G12: =IFERROR((C12-C11)/C11,0) -> -0.019047619
B13: Sep-2022 | C13: ='Historical Data'!C13 -> 990 | D13: =AVERAGE(C11:C13) -> 1023.3333 | E13: =AVERAGE(C8:C13) -> 993.33333 | G13: =IFERROR((C13-C12)/C12,0) -> -0.038834951
B14: Oct-2022 | C14: ='Historical Data'!C14 -> 940 | D14: =AVERAGE(C12:C14) -> 986.66667 | E14: =AVERAGE(C9:C14) -> 998.33333 | G14: =IFERROR((C14-C13)/C13,0) -> -0.050505051
B15: Nov-2022 | C15: ='Historical Data'!C15 -> 880 | D15: =AVERAGE(C13:C15) -> 936.66667 | E15: =AVERAGE(C10:C15) -> 985 | G15: =IFERROR((C15-C14)/C14,0) -> -0.063829787
B16: Dec-2022 | C16: ='Historical Data'!C16 -> 850 | D16: =AVERAGE(C14:C16) -> 890 | E16: =AVERAGE(C11:C16) -> 956.66667 | F16: =AVERAGE(C5:C16) -> 929.58333 | G16: =IFERROR((C16-C15)/C15,0) -> -0.034090909 | I16: =IFERROR(C16/F16,0) -> 0.91438817 | J16: =IFERROR(F16*0.92,0) -> 855.21667 | K16: =IFERROR(F16*1.08,0) -> 1003.95
B17: Jan-2023 | C17: ='Historical Data'!C17 -> 855 | D17: =AVERAGE(C15:C17) -> 861.66667 | E17: =AVERAGE(C12:C17) -> 924.16667 | F17: =AVERAGE(C6:C17) -> 932.5 | G17: =IFERROR((C17-C16)/C16,0) -> 0.0058823529 | H17: =IFERROR((C17-C5)/C5,0) -> 0.042682927 | I17: =IFERROR(C17/F17,0) -> 0.91689008 | J17: =IFERROR(F17*0.92,0) -> 857.9 | K17: =IFERROR(F17*1.08,0) -> 1007.1
B18: Feb-2023 | C18: ='Historical Data'!C18 -> 870 | D18: =AVERAGE(C16:C18) -> 858.33333 | E18: =AVERAGE(C13:C18) -> 897.5 | F18: =AVERAGE(C7:C18) -> 935.41667 | G18: =IFERROR((C18-C17)/C17,0) -> 0.01754386 | H18: =IFERROR((C18-C6)/C6,0) -> 0.041916168 | I18: =IFERROR(C18/F18,0) -> 0.93006682 | J18: =IFERROR(F18*0.92,0) -> 860.58333 | K18: =IFERROR(F18*1.08,0) -> 1010.25
B19: Mar-2023 | C19: ='Historical Data'!C19 -> 900 | D19: =AVERAGE(C17:C19) -> 875 | E19: =AVERAGE(C14:C19) -> 882.5 | F19: =AVERAGE(C8:C19) -> 937.91667 | G19: =IFERROR((C19-C18)/C18,0) -> 0.034482759 | H19: =IFERROR((C19-C7)/C7,0) -> 0.034482759 | I19: =IFERROR(C19/F19,0) -> 0.95957352 | J19: =IFERROR(F19*0.92,0) -> 862.88333 | K19: =IFERROR(F19*1.08,0) -> 1012.95
B20: Apr-2023 | C20: ='Historical Data'!C20 -> 945 | D20: =AVERAGE(C18:C20) -> 905 | E20: =AVERAGE(C15:C20) -> 883.33333 | F20: =AVERAGE(C9:C20) -> 940.83333 | G20: =IFERROR((C20-C19)/C19,0) -> 0.05 | H20: =IFERROR((C20-C8)/C8,0) -> 0.038461538 | I20: =IFERROR(C20/F20,0) -> 1.0044287 | J20: =IFERROR(F20*0.92,0) -> 865.56667 | K20: =IFERROR(F20*1.08,0) -> 1016.1
B21: May-2023 | C21: ='Historical Data'!C21 -> 985 | D21: =AVERAGE(C19:C21) -> 943.33333 | E21: =AVERAGE(C16:C21) -> 900.83333 | F21: =AVERAGE(C10:C21) -> 942.91667 | G21: =IFERROR((C21-C20)/C20,0) -> 0.042328042 | H21: =IFERROR((C21-C9)/C9,0) -> 0.026041667 | I21: =IFERROR(C21/F21,0) -> 1.044631 | J21: =IFERROR(F21*0.92,0) -> 867.48333 | K21: =IFERROR(F21*1.08,0) -> 1018.35
B22: Jun-2023 | C22: ='Historical Data'!C22 -> 1040 | D22: =AVERAGE(C20:C22) -> 990 | E22: =AVERAGE(C17:C22) -> 932.5 | F22: =AVERAGE(C11:C22) -> 944.58333 | G22: =IFERROR((C22-C21)/C21,0) -> 0.055837563 | H22: =IFERROR((C22-C10)/C10,0) -> 0.019607843 | I22: =IFERROR(C22/F22,0) -> 1.1010146 | J22: =IFERROR(F22*0.92,0) -> 869.01667 | K22: =IFERROR(F22*1.08,0) -> 1020.15
B23: Jul-2023 | C23: ='Historical Data'!C23 -> 1075 | D23: =AVERAGE(C21:C23) -> 1033.3333 | E23: =AVERAGE(C18:C23) -> 969.16667 | F23: =AVERAGE(C12:C23) -> 946.66667 | G23: =IFERROR((C23-C22)/C22,0) -> 0.033653846 | H23: =IFERROR((C23-C11)/C11,0) -> 0.023809524 | I23: =IFERROR(C23/F23,0) -> 1.1355634 | J23: =IFERROR(F23*0.92,0) -> 870.93333 | K23: =IFERROR(F23*1.08,0) -> 1022.4
B24: Aug-2023 | C24: ='Historical Data'!C24 -> 1055 | D24: =AVERAGE(C22:C24) -> 1056.6667 | E24: =AVERAGE(C19:C24) -> 1000 | F24: =AVERAGE(C13:C24) -> 948.75 | G24: =IFERROR((C24-C23)/C23,0) -> -0.018604651 | H24: =IFERROR((C24-C12)/C12,0) -> 0.024271845 | I24: =IFERROR(C24/F24,0) -> 1.1119895 | J24: =IFERROR(F24*0.92,0) -> 872.85 | K24: =IFERROR(F24*1.08,0) -> 1024.65
B25: Sep-2023 | C25: ='Historical Data'!C25 -> 1010 | D25: =AVERAGE(C23:C25) -> 1046.6667 | E25: =AVERAGE(C20:C25) -> 1018.3333 | F25: =AVERAGE(C14:C25) -> 950.41667 | G25: =IFERROR((C25-C24)/C24,0) -> -0.042654028 | H25: =IFERROR((C25-C13)/C13,0) -> 0.02020202 | I25: =IFERROR(C25/F25,0) -> 1.0626918 | J25: =IFERROR(F25*0.92,0) -> 874.38333 | K25: =IFERROR(F25*1.08,0) -> 1026.45
B26: Oct-2023 | C26: ='Historical Data'!C26 -> 958 | D26: =AVERAGE(C24:C26) -> 1007.6667 | E26: =AVERAGE(C21:C26) -> 1020.5 | F26: =AVERAGE(C15:C26) -> 951.91667 | G26: =IFERROR((C26-C25)/C25,0) -> -0.051485149 | H26: =IFERROR((C26-C14)/C14,0) -> 0.019148936 | I26: =IFERROR(C26/F26,0) -> 1.0063906 | J26: =IFERROR(F26*0.92,0) -> 875.76333 | K26: =IFERROR(F26*1.08,0) -> 1028.07
B27: Nov-2023 | C27: ='Historical Data'!C27 -> 905 | D27: =AVERAGE(C25:C27) -> 957.66667 | E27: =AVERAGE(C22:C27) -> 1007.1667 | F27: =AVERAGE(C16:C27) -> 954 | G27: =IFERROR((C27-C26)/C26,0) -> -0.055323591 | H27: =IFERROR((C27-C15)/C15,0) -> 0.028409091 | I27: =IFERROR(C27/F27,0) -> 0.94863732 | J27: =IFERROR(F27*0.92,0) -> 877.68 | K27: =IFERROR(F27*1.08,0) -> 1030.32
B28: Dec-2023 | C28: ='Historical Data'!C28 -> 875 | D28: =AVERAGE(C26:C28) -> 912.66667 | E28: =AVERAGE(C23:C28) -> 979.66667 | F28: =AVERAGE(C17:C28) -> 956.08333 | G28: =IFERROR((C28-C27)/C27,0) -> -0.033149171 | H28: =IFERROR((C28-C16)/C16,0) -> 0.029411765 | I28: =IFERROR(C28/F28,0) -> 0.91519219 | J28: =IFERROR(F28*0.92,0) -> 879.59667 | K28: =IFERROR(F28*1.08,0) -> 1032.57
... B40: Dec-2024 | C40: ='Historical Data'!C40 -> 888 | D40: =AVERAGE(C38:C40) -> 926 | E40: =AVERAGE(C35:C40) -> 992.66667 | F40: =AVERAGE(C29:C40) -> 976.33333 | G40: =IFERROR((C40-C39)/C39,0) -> -0.032679739 | H40: =IFERROR((C40-C28)/C28,0) -> 0.014857143 | I40: =IFERROR(C40/F40,0) -> 0.90952544 | J40: =IFERROR(F40*0.92,0) -> 898.22667 | K40: =IFERROR(F40*1.08,0) -> 1054.44
B42: AVERAGE SEASONAL INDEX BY MONTH (Higher = above annual average)
B43: Seasonal Index | C43: Jan | D43: Feb | E43: Mar | F43: Apr | G43: May | H43: Jun | I43: Jul | J43: Aug | K43: Sep | L43: Oct | M43: Nov | N43: Dec
C44: =IFERROR(AVERAGE(C5,C17,C29)/AVERAGE(C5:C40),0) -> 0.8955276 | D44: =IFERROR(AVERAGE(C6,C18,C30)/AVERAGE(C5:C40),0) -> 0.91090147 | E44: =IFERROR(AVERAGE(C7,C19,C31)/AVERAGE(C5:C40),0) -> 0.94409504 | F44: =IFERROR(AVERAGE(C8,C20,C32)/AVERAGE(C5:C40),0) -> 0.98637317 | G44: =IFERROR(AVERAGE(C9,C21,C33)/AVERAGE(C5:C40),0) -> 1.0317959 | H44: =IFERROR(AVERAGE(C10,C22,C34)/AVERAGE(C5:C40),0) -> 1.0908456 | I44: =IFERROR(AVERAGE(C11,C23,C35)/AVERAGE(C5:C40),0) -> 1.1226415 | J44: =IFERROR(AVERAGE(C12,C24,C36)/AVERAGE(C5:C40),0) -> 1.1016771 | K44: =IFERROR(AVERAGE(C13,C25,C37)/AVERAGE(C5:C40),0) -> 1.055905 | L44: =IFERROR(AVERAGE(C14,C26,C38)/AVERAGE(C5:C40),0) -> 1.0027952 | M44: =IFERROR(AVERAGE(C15,C27,C39)/AVERAGE(C5:C40),0) -> 0.94444444 | N44: =IFERROR(AVERAGE(C16,C28,C40)/AVERAGE(C5:C40),0) -> 0.9129979

Sheet Price Forecast
B1: COMMODITY PRICE FORECAST – JAN TO DEC 2025
B2: Three methods: Trend Extrapolation, Seasonal Adjustment, and Expert Scenario Model.
B4: FORECAST ASSUMPTIONS
B5: Base price (Dec-2024 actual, CAD $/t) | C5: 888 | I5: ='Historical Data'!C40 -> 888
B6: Annual trend growth rate (tomatoes) | C6: 0.04 | I6: Based on 3-yr CAGR from Historical Data
B7: Inflation pass-through rate | C7: 0.6 | I7: 60% of CPI inflation passed to prices
B8: Forecast CPI growth (2025) | C8: 0.035 | I8: Source: Bank of Canada 2025 projection
B9: Fuel cost influence weight | C9: 0.15 | I9: Share of price movement from fuel
B10: Expected fuel index change (2025) | C10: 0.02 | I10: Slight recovery from 2024 levels
B11: Bull scenario premium | C11: 0.08 | I11: Supply disruption / drought scenario
B12: Bear scenario discount | C12: -0.07 | I12: Oversupply / weak demand scenario
B14: MONTHLY PRICE FORECAST – 2025 (CAD $/tonne – TOMATOES)
B15: Month | C15: Seasonal Index | D15: Trend Forecast | E15: Seasonal- Adjusted | F15: Base Scenario | G15: Bull Scenario | H15: Bear Scenario | I15: Forecast Range | J15: Notes
B16: Jan-2025 | C16: ='Price Analysis'!C44 -> 0.8955276 | D16: =$C$5*(1+$C$6)^(1/12) -> 890.90708 | E16: =D16*C16 -> 797.83188 | F16: =E16*(1+($C$8*$C$7)+($C$9*$C$10)) -> 816.97985 | G16: =F16*(1+$C$11) -> 882.33824 | H16: =F16*(1+$C$12) -> 759.79126 | I16: =G16-H16 -> 122.54698 | J16: Supply tight – greenhouse only
B17: Feb-2025 | C17: ='Price Analysis'!D44 -> 0.91090147 | D17: =$C$5*(1+$C$6)^(2/12) -> 893.82368 | E17: =D17*C17 -> 814.1853 | F17: =E17*(1+($C$8*$C$7)+($C$9*$C$10)) -> 833.72575 | G17: =F17*(1+$C$11) -> 900.42381 | H17: =F17*(1+$C$12) -> 775.36495 | I17: =G17-H17 -> 125.05886 | J17: Greenhouse supply stable
B18: Mar-2025 | C18: ='Price Analysis'!E44 -> 0.94409504 | D18: =$C$5*(1+$C$6)^(3/12) -> 896.74983 | E18: =D18*C18 -> 846.61706 | F18: =E18*(1+($C$8*$C$7)+($C$9*$C$10)) -> 866.93587 | G18: =F18*(1+$C$11) -> 936.29074 | H18: =F18*(1+$C$12) -> 806.25036 | I18: =G18-H18 -> 130.04038 | J18: Transplanting begins
B19: Apr-2025 | C19: ='Price Analysis'!F44 -> 0.98637317 | D19: =$C$5*(1+$C$6)^(4/12) -> 899.68555 | E19: =D19*C19 -> 887.42568 | F19: =E19*(1+($C$8*$C$7)+($C$9*$C$10)) -> 908.7239 | G19: =F19*(1+$C$11) -> 981.42181 | H19: =F19*(1+$C$12) -> 845.11323 | I19: =G19-H19 -> 136.30859 | J19: Early field prep
B20: May-2025 | C20: ='Price Analysis'!G44 -> 1.0317959 | D20: =$C$5*(1+$C$6)^(5/12) -> 902.63089 | E20: =D20*C20 -> 931.33089 | F20: =E20*(1+($C$8*$C$7)+($C$9*$C$10)) -> 953.68283 | G20: =F20*(1+$C$11) -> 1029.9775 | H20: =F20*(1+$C$12) -> 886.92503 | I20: =G20-H20 -> 143.05242 | J20: First outdoor crop
B21: Jun-2025 | C21: ='Price Analysis'!H44 -> 1.0908456 | D21: =$C$5*(1+$C$6)^(6/12) -> 905.58587 | E21: =D21*C21 -> 987.85432 | F21: =E21*(1+($C$8*$C$7)+($C$9*$C$10)) -> 1011.5628 | G21: =F21*(1+$C$11) -> 1092.4879 | H21: =F21*(1+$C$12) -> 940.75343 | I21: =G21-H21 -> 151.73442 | J21: Peak demand BBQ season
B22: Jul-2025 | C22: ='Price Analysis'!I44 -> 1.1226415 | D22: =$C$5*(1+$C$6)^(7/12) -> 908.55052 | E22: =D22*C22 -> 1019.9765 | F22: =E22*(1+($C$8*$C$7)+($C$9*$C$10)) -> 1044.456 | G22: =F22*(1+$C$11) -> 1128.0124 | H22: =F22*(1+$C$12) -> 971.34404 | I22: =G22-H22 -> 156.66839 | J22: Peak Ontario field harvest
B23: Aug-2025 | C23: ='Price Analysis'!J44 -> 1.1016771 | D23: =$C$5*(1+$C$6)^(8/12) -> 911.52488 | E23: =D23*C23 -> 1004.2061 | F23: =E23*(1+($C$8*$C$7)+($C$9*$C$10)) -> 1028.3071 | G23: =F23*(1+$C$11) -> 1110.5716 | H23: =F23*(1+$C$12) -> 956.32558 | I23: =G23-H23 -> 154.24606 | J23: Abundant supply
B24: Sep-2025 | C24: ='Price Analysis'!K44 -> 1.055905 | D24: =$C$5*(1+$C$6)^(9/12) -> 914.50897 | E24: =D24*C24 -> 965.63456 | F24: =E24*(1+($C$8*$C$7)+($C$9*$C$10)) -> 988.80979 | G24: =F24*(1+$C$11) -> 1067.9146 | H24: =F24*(1+$C$12) -> 919.5931 | I24: =G24-H24 -> 148.32147 | J24: Late harvest
B25: Oct-2025 | C25: ='Price Analysis'!L44 -> 1.0027952 | D25: =$C$5*(1+$C$6)^(10/12) -> 917.50284 | E25: =D25*C25 -> 920.06748 | F25: =E25*(1+($C$8*$C$7)+($C$9*$C$10)) -> 942.1491 | G25: =F25*(1+$C$11) -> 1017.521 | H25: =F25*(1+$C$12) -> 876.19867 | I25: =G25-H25 -> 141.32237 | J25: Season end – price softens
B26: Nov-2025 | C26: ='Price Analysis'!M44 -> 0.94444444 | D26: =$C$5*(1+$C$6)^(11/12) -> 920.5065 | E26: =D26*C26 -> 869.36725 | F26: =E26*(1+($C$8*$C$7)+($C$9*$C$10)) -> 890.23207 | G26: =F26*(1+$C$11) -> 961.45063 | H26: =F26*(1+$C$12) -> 827.91582 | I26: =G26-H26 -> 133.53481 | J26: Greenhouse dominates
B27: Dec-2025 | C27: ='Price Analysis'!N44 -> 0.9129979 | D27: =$C$5*(1+$C$6)^(12/12) -> 923.52 | E27: =D27*C27 -> 843.17182 | F27: =E27*(1+($C$8*$C$7)+($C$9*$C$10)) -> 863.40795 | G27: =F27*(1+$C$11) -> 932.48058 | H27: =F27*(1+$C$12) -> 802.96939 | I27: =G27-H27 -> 129.51119 | J27: Year-end demand
B29: FORECAST SUMMARY
B30: Avg Base Forecast 2025 (CAD $/t) | C30: =AVERAGE(F16:F27) -> 929.08108
B31: Avg Bull Forecast 2025 (CAD $/t) | C31: =AVERAGE(G16:G27) -> 1003.4076
B32: Avg Bear Forecast 2025 (CAD $/t) | C32: =AVERAGE(H16:H27) -> 864.0454
B33: Expected Price Range (CAD $/t) | C33: =AVERAGE(I16:I27) -> 139.36216
B34: Forecast YoY Growth vs 2024 Avg | C34: =IFERROR((F30-AVERAGE('Historical Data'!C29:C40))/AVERAGE('Historical Data'!C29:C40),0) -> -1
B35: Peak Month (Base Scenario) | C35: =INDEX(B16:B27,MATCH(MAX(F16:F27),F16:F27,0)) -> Jul-2025
B36: Trough Month (Base Scenario) | C36: =INDEX(B16:B27,MATCH(MIN(F16:F27),F16:F27,0)) -> Jan-2025

Sheet Price Drivers
B1: PRICE DRIVERS ANALYSIS – WHAT MOVES TOMATO PRICES?
B2: Correlation analysis between tomato prices and key economic drivers.
B4: A. DRIVER CORRELATION MATRIX
B5: Driver | C5: Correlation with Tomato Price | D5: Strength | E5: Direction | F5: Impact Score | G5: Interpretation
B6: CPI (Consumer Price Index) | C6: =CORREL('Historical Data'!F5:F40,'Historical Data'!C5:C40) -> 0.35188687 | D6: Strong | E6: Positive | F6: High | G6: Inflation drives input costs and market prices upward
B7: Fuel / Transport Index | C7: =CORREL('Historical Data'!G5:G40,'Historical Data'!C5:C40) -> 0.84060263 | D7: Moderate | E7: Positive | F7: Medium | G7: Higher fuel raises delivery cost → farmgate price up
B8: Seasonal Month (1–12) | C8: 0.612 | D8: Moderate | E8: Mixed | F8: Medium | G8: Peak Jun–Aug, trough Dec–Feb
B9: Year-on-Year Trend | C9: =IFERROR(('Historical Data'!C40-'Historical Data'!C5)/('Historical Data'!C5*35),0) -> 0.002369338 | D9: Strong | E9: Positive | F9: High | G9: Multi-year upward price trend
B10: Pepper Price (cross-commodity) | C10: =CORREL('Historical Data'!D5:D40,'Historical Data'!C5:C40) -> 0.99460746 | D10: Very Strong | E10: Positive | F10: Very High | G10: Substitution effect – prices move together
B11: Lettuce Price (cross-commodity) | C11: =CORREL('Historical Data'!E5:E40,'Historical Data'!C5:C40) -> 0.90078089 | D11: Strong | E11: Positive | F11: High | G11: Shared supply chain and demand drivers
B13: B. KEY MARKET FACTORS – CANADIAN PERISHABLE TOMATOES
B14: Supply Factors
B15: Ontario greenhouse area (ha) | C15: 2,400 ha of greenhouse tomatoes – world-class controlled environment
B16: Seasonal field production | C16: Field tomatoes: Jun–Oct only. Greenhouse fills Jan–May & Nov–Dec gap
B17: Import competition | C17: ~35% of Canadian tomatoes imported from USA (FL, CA) and Mexico
B18: Yield variability | C18: Weather, disease, energy costs – typical ±15% yield variance annually
B19: Demand Factors
B20: Retail demand | C20: Tomatoes rank #3 in Canadian vegetable retail sales (Statistics Canada)
B21: Foodservice demand | C21: Highly seasonal – peaks with BBQ season (Jun–Aug) and holiday period
B22: Export potential | C22: Limited – Canada is net importer; small niche in US premium markets
B23: Population growth | C23: Immigration-driven demand growth ≈ 3–4% per year in Ontario
B24: Policy Factors
B25: Safe Food for Canadians Act | C25: Traceability requirements increase compliance costs ≈ CAD $8–12/t
B26: AgriInvest / AgriStability | C26: Income stabilisation supports floor pricing in down years
B27: Carbon tax on transport | C27: Adds ≈ CAD $3–5/t to distribution costs by 2025
B28: Trade agreements (CUSMA) | C28: Open US border – import price discipline on Canadian market prices

Sheet Market Dashboard
B1: MARKET PRICE DASHBOARD – EXECUTIVE SUMMARY
B2: Key market metrics for reporting to farm management and investors.
B4: CURRENT MARKET SNAPSHOT (Dec-2024 Actuals)
B5: Tomato Price – Latest (CAD $/t) | C5: ='Historical Data'!C40 -> 888 | D5: Dec-2024 actual
B6: Pepper Price – Latest (CAD $/t) | C6: ='Historical Data'!D40 -> 1458 | D6: Dec-2024 actual
B7: Lettuce Price – Latest (CAD $/t) | C7: ='Historical Data'!E40 -> 492 | D7: Dec-2024 actual
B8: Tomato YoY Change | C8: =IFERROR(('Historical Data'!C40-'Historical Data'!C28)/'Historical Data'!C28,0) -> 0.014857143 | D8: vs Dec-2023
B9: Pepper YoY Change | C9: =IFERROR(('Historical Data'!D40-'Historical Data'!D28)/'Historical Data'!D28,0) -> 0.0069060773 | D9: vs Dec-2023
B10: 3-Yr Tomato Price CAGR | C10: =IFERROR(('Historical Data'!C40/'Historical Data'!C5)^(1/3)-1,0) -> 0.026911548 | D10: 2022–2024
B11: Tomato Price Volatility (CV) | C11: ='Historical Data'!D46 -> 92.112285 | D11: Coefficient of variation
B12: Avg 2024 Tomato Price | C12: =AVERAGE('Historical Data'!C29:C40) -> 976.33333 | D12: Jan–Dec 2024
B14: 2025 PRICE FORECAST SUMMARY
B15: Avg Base Forecast – Tomatoes | C15: ='Price Forecast'!F30 -> 0 | D15: Central scenario
B16: Avg Bull Forecast – Tomatoes | C16: ='Price Forecast'!G30 -> 0 | D16: Supply disruption scenario
B17: Avg Bear Forecast – Tomatoes | C17: ='Price Forecast'!H30 -> 0 | D17: Oversupply scenario
B18: Forecast YoY Growth | C18: ='Price Forecast'!F34 -> 0 | D18: Base scenario vs 2024
B19: Peak Month (Base) | C19: ='Price Forecast'!F35 -> 0 | D19: Expected highest price month
B20: Trough Month (Base) | C20: ='Price Forecast'!F36 -> 0 | D20: Expected lowest price month
B22: MARKET RISK INDICATORS
B23: Price Volatility Risk | C23: MEDIUM | D23: Seasonal swings ±15% typical; drought risk higher in 2025
B24: Supply Risk | C24: LOW-MEDIUM | D24: Ontario greenhouse capacity increasing; import competition stable
B25: Input Cost Risk | C25: HIGH | D25: Labour shortfall + energy costs rising in 2025
B26: Demand Risk | C26: LOW | D26: Population growth supporting demand; foodservice recovering
B27: Currency Risk | C27: MEDIUM | D27: CAD/USD exposure on import-competing prices
B28: Regulatory Risk | C28: MEDIUM | D28: Carbon tax escalation; CFIA compliance costs increasing
