Workbook

Sheet Assumptions
B1: FARM FINANCIAL BUDGET – KEY ASSUMPTIONS
B2: Blue cells = editable inputs. All other sheets link here automatically.
B4: FARM PROFILE
B5: Farm name | C5: Maple Leaf Fresh Farms | E5: Ontario, Canada
B6: Primary crop | C6: Fresh Tomatoes (Greenhouse) | E6: Solanum lycopersicum
B7: Farm size (hectares) | C7: 12 | E7: Greenhouse + field combined
B8: Planning year | C8: 2025 | E8: Budget year
B9: Currency | C9: CAD | E9: Canadian Dollar
B11: PRODUCTION
B12: Yield per hectare (tonnes/ha) | C12: 85 | E12: Source: OMAFRA Greenhouse Veg Guide 2024
B13: Total expected production (tonnes) | C13: =C12*C7 -> 1020 | E13: Yield × farm size
B14: Grade A proportion | C14: 0.82 | E14: Premium quality – direct retail
B15: Grade B proportion | C15: 0.15 | E15: Wholesale/processing
B16: Culls / unsaleable | C16: 0.03 | E16: Composted or discarded
B18: REVENUE
B19: Grade A selling price (CAD $/tonne) | C19: 1050 | E19: Premium retail & food service
B20: Grade B selling price (CAD $/tonne) | C20: 620 | E20: Wholesale market price
B21: Government grants / subsidies (CAD $) | C21: 18000 | E21: AAFC AgriInvest allocation
B23: VARIABLE COSTS (CAD $/tonne produced)
B24: Seeds & transplants | C24: 32 | E24: Sakata hybrid seed 2024
B25: Fertilisers & amendments | C25: 48 | E25: NPK + calcium nitrate programme
B26: Pesticides & fungicides (IPM) | C26: 16 | E26: Integrated pest management
B27: Irrigation & water | C27: 14 | E27: Municipal metered rate
B28: Greenhouse energy (gas+LED) | C28: 38 | E28: Natural gas + supplemental lighting
B29: Harvest & packing labour | C29: 52 | E29: @ CAD $17.50/hr seasonal
B30: Packaging materials | C30: 24 | E30: 20 kg clamshells + pallets
B31: Transport to market | C31: 42 | E31: Reefer truck, avg 180 km
B32: Casual labour – growing | C32: 35 | E32: Greenhouse workers
B33: Crop insurance premium | C33: 18 | E33: AgriInsurance OMAFRA
B35: FIXED COSTS (CAD $/year)
B36: Land / greenhouse lease | C36: 95000 | E36: Annual lease – 12 ha facility
B37: Equipment depreciation | C37: 42000 | E37: 10-yr straight-line on CAD $420k assets
B38: Management salaries | C38: 120000 | E38: Farm manager + assistant
B39: Office & administration | C39: 18000 | E39: Accounting, IT, communications
B40: Insurance – property & liability | C40: 22000 | E40: Commercial farm policy
B41: Regulatory & compliance | C41: 9500 | E41: CFIA, Safe Food for Canadians Act
B42: Interest on operating loan | C42: 14000 | E42: CAD $200k @ 7% p.a.
B43: Repairs & maintenance | C43: 28000 | E43: 3% of asset value
B45: CASH FLOW TIMING – Variable Cost Monthly %
B46: Jan | C46: 0.04 | E46: Low – heating, maintenance only
...

Sheet Enterprise Budget
B1: ENTERPRISE BUDGET – FRESH TOMATOES (Per Hectare & Whole Farm)
B2: Shows profitability per hectare vs whole farm. All values link to Assumptions sheet.
B4: Item | C4: Per Hectare (CAD $) | D4: Whole Farm (CAD $) | E4: % of Revenue | F4: Notes
B5: A. REVENUE
B6: Grade A Sales | C6: =Assumptions!C12*Assumptions!C14*Assumptions!C19 -> 73185 | D6: =C6*Assumptions!C7 -> 878220 | E6: =IFERROR(C6/C9,0) -> 0.88612423 | F6: Grade A proportion × yield/ha × price
B7: Grade B Sales | C7: =Assumptions!C12*Assumptions!C15*Assumptions!C20 -> 7905 | D7: =C7*Assumptions!C7 -> 94860 | E7: =IFERROR(C7/C9,0) -> 0.095713767 | F7: Grade B proportion × yield/ha × price
B8: Government Grants / Subsidies | C8: =Assumptions!C21/Assumptions!C7 -> 1500 | D8: =Assumptions!C21 -> 18000 | E8: =IFERROR(C8/C9,0) -> 0.018162005 | F8: AAFC AgriInvest – allocated per ha
B9: TOTAL REVENUE | C9: =SUM(C6:C8) -> 82590 | D9: =SUM(D6:D8) -> 991080 | E9: =1 -> 1
B11: B. VARIABLE COSTS
B12: Seeds & Transplants | C12: =Assumptions!C24*Assumptions!C12 -> 2720 | D12: =C12*Assumptions!C7 -> 32640 | E12: =IFERROR(C12/C9,0) -> 0.032933769
B13: Fertilisers & Amendments | C13: =Assumptions!C25*Assumptions!C12 -> 4080 | D13: =C13*Assumptions!C7 -> 48960 | E13: =IFERROR(C13/C9,0) -> 0.049400654
B14: Pesticides & Fungicides | C14: =Assumptions!C26*Assumptions!C12 -> 1360 | D14: =C14*Assumptions!C7 -> 16320 | E14: =IFERROR(C14/C9,0) -> 0.016466885
B15: Irrigation & Water | C15: =Assumptions!C27*Assumptions!C12 -> 1190 | D15: =C15*Assumptions!C7 -> 14280 | E15: =IFERROR(C15/C9,0) -> 0.014408524
B16: Greenhouse Energy | C16: =Assumptions!C28*Assumptions!C12 -> 3230 | D16: =C16*Assumptions!C7 -> 38760 | E16: =IFERROR(C16/C9,0) -> 0.039108851
B17: Harvest & Packing Labour | C17: =Assumptions!C29*Assumptions!C12 -> 4420 | D17: =C17*Assumptions!C7 -> 53040 | E17: =IFERROR(C17/C9,0) -> 0.053517375
B18: Packaging Materials | C18: =Assumptions!C30*Assumptions!C12 -> 2040 | D18: =C18*Assumptions!C7 -> 24480 | E18: =IFERROR(C18/C9,0) -> 0.024700327
B19: Transport to Market | C19: =Assumptions!C31*Assumptions!C12 -> 3570 | D19: =C19*Assumptions!C7 -> 42840 | E19: =IFERROR(C19/C9,0) -> 0.043225572
B20: Casual Labour – Growing | C20: =Assumptions!C32*Assumptions!C12 -> 2975 | D20: =C20*Assumptions!C7 -> 35700 | E20: =IFERROR(C20/C9,0) -> 0.03602131
B21: Crop Insurance Premium | C21: =Assumptions!C33*Assumptions!C12 -> 1530 | D21: =C21*Assumptions!C7 -> 18360 | E21: =IFERROR(C21/C9,0) -> 0.018525245
B22: TOTAL VARIABLE COSTS | C22: =SUM(C12:C21) -> 27115 | D22: =SUM(D12:D21) -> 325380 | E22: =IFERROR(C22/C9,0) -> 0.32830851
B23: GROSS MARGIN (Revenue – Variable Costs) | C23: =C9-C22 -> 55475 | D23: =D9-D22 -> 665700 | E23: =IFERROR(C23/C9,0) -> 0.67169149
B25: C. FIXED COSTS (Whole Farm – Allocated per Hectare)
B26: Land / Greenhouse Lease | C26: =Assumptions!C36/Assumptions!C7 -> 7916.6667 | D26: =Assumptions!C36 -> 95000 | E26: =IFERROR(C26/C9,0) -> 0.095855027
B27: Equipment Depreciation | C27: =Assumptions!C37/Assumptions!C7 -> 3500 | D27: =Assumptions!C37 -> 42000 | E27: =IFERROR(C27/C9,0) -> 0.042378012
B28: Management Salaries | C28: =Assumptions!C38/Assumptions!C7 -> 10000 | D28: =Assumptions!C38 -> 120000 | E28: =IFERROR(C28/C9,0) -> 0.12108003
B29: Office & Administration | C29: =Assumptions!C39/Assumptions!C7 -> 1500 | D29: =Assumptions!C39 -> 18000 | E29: =IFERROR(C29/C9,0) -> 0.018162005
B30: Insurance – Property & Liability | C30: =Assumptions!C40/Assumptions!C7 -> 1833.3333 | D30: =Assumptions!C40 -> 22000 | E30: =IFERROR(C30/C9,0) -> 0.022198006
B31: Regulatory & Compliance | C31: =Assumptions!C41/Assumptions!C7 -> 791.66667 | D31: =Assumptions!C41 -> 9500 | E31: =IFERROR(C31/C9,0) -> 0.0095855027
B32: Interest on Operating Loan | C32: =Assumptions!C42/Assumptions!C7 -> 1166.6667 | D32: =Assumptions!C42 -> 14000 | E32: =IFERROR(C32/C9,0) -> 0.014126004
B33: Repairs & Maintenance | C33: =Assumptions!C43/Assumptions!C7 -> 2333.3333 | D33: =Assumptions!C43 -> 28000 | E33: =IFERROR(C33/C9,0) -> 0.028252008
B34: TOTAL FIXED COSTS | C34: =SUM(C26:C33) -> 29041.667 | D34: =SUM(D26:D33) -> 348500 | E34: =IFERROR(C34/C9,0) -> 0.3516366
B36: NET FARM INCOME (Gross Margin – Fixed Costs) | C36: =C23-C34 -> 26433.333 | D36: =D23-D34 -> 317200 | E36: =IFERROR(C36/C9,0) -> 0.32005489
B37: KEY RATIOS
B38: Gross Margin % | C38: =IFERROR(C23/C9,0) -> 0.67169149
B39: Net Farm Income Margin % | C39: =IFERROR(C36/C9,0) -> 0.32005489
B40: Variable Cost Ratio | C40: =IFERROR(C22/C9,0) -> 0.32830851
B41: Fixed Cost per Tonne (CAD $) | C41: =IFERROR(D34/Assumptions!C13,0) -> 341.66667

Sheet Cash Flow Budget
B1: 12-MONTH CASH FLOW BUDGET – MAPLE LEAF FRESH FARMS (2025)
B2: Monthly cash position. Revenue and cost timing driven by Assumptions sheet monthly % splits.
B4: Item | C4: Jan | D4: Feb | E4: Mar | F4: Apr | G4: May | H4: Jun | I4: Jul | J4: Aug | K4: Sep | L4: Oct | M4: Nov | N4: Dec | P4: Annual Total
B5: A. CASH INFLOWS
B6: Grade A Sales Revenue | C6: ='Enterprise Budget'!D6*Assumptions!C60 -> 0 | D6: ='Enterprise Budget'!D6*Assumptions!C61 -> 0 | E6: ='Enterprise Budget'!D6*Assumptions!C62 -> 17564.4 | F6: ='Enterprise Budget'!D6*Assumptions!C63 -> 43911 | G6: ='Enterprise Budget'!D6*Assumptions!C64 -> 87822 | H6: ='Enterprise Budget'!D6*Assumptions!C65 -> 122950.8 | I6: ='Enterprise Budget'!D6*Assumptions!C66 -> 140515.2 | J6: ='Enterprise Budget'!D6*Assumptions!C67 -> 140515.2 | K6: ='Enterprise Budget'!D6*Assumptions!C68 -> 122950.8 | L6: ='Enterprise Budget'!D6*Assumptions!C69 -> 105386.4 | M6: ='Enterprise Budget'!D6*Assumptions!C70 -> 61475.4 | N6: ='Enterprise Budget'!D6*Assumptions!C71 -> 35128.8 | P6: =SUM(C6:N6) -> 878220
B7: Grade B Sales Revenue | C7: ='Enterprise Budget'!D7*Assumptions!C60 -> 0 | D7: ='Enterprise Budget'!D7*Assumptions!C61 -> 0 | E7: ='Enterprise Budget'!D7*Assumptions!C62 -> 1897.2 | F7: ='Enterprise Budget'!D7*Assumptions!C63 -> 4743 | G7: ='Enterprise Budget'!D7*Assumptions!C64 -> 9486 | H7: ='Enterprise Budget'!D7*Assumptions!C65 -> 13280.4 | I7: ='Enterprise Budget'!D7*Assumptions!C66 -> 15177.6 | J7: ='Enterprise Budget'!D7*Assumptions!C67 -> 15177.6 | K7: ='Enterprise Budget'!D7*Assumptions!C68 -> 13280.4 | L7: ='Enterprise Budget'!D7*Assumptions!C69 -> 11383.2 | M7: ='Enterprise Budget'!D7*Assumptions!C70 -> 6640.2 | N7: ='Enterprise Budget'!D7*Assumptions!C71 -> 3794.4 | P7: =SUM(C7:N7) -> 94860
B8: Government Grants | C8: =0 -> 0 | D8: =0 -> 0 | E8: =0 -> 0 | F8: =0 -> 0 | G8: =0 -> 0 | H8: =0 -> 0 | I8: ='Enterprise Budget'!D8 -> 18000 | J8: =0 -> 0 | K8: =0 -> 0 | L8: =0 -> 0 | M8: =0 -> 0 | N8: =0 -> 0 | P8: =SUM(C8:N8) -> 18000
B9: TOTAL CASH INFLOWS | C9: =SUM(C6:C8) -> 0 | D9: =SUM(D6:D8) -> 0 | E9: =SUM(E6:E8) -> 19461.6 | F9: =SUM(F6:F8) -> 48654 | G9: =SUM(G6:G8) -> 97308 | H9: =SUM(H6:H8) -> 136231.2 | I9: =SUM(I6:I8) -> 173692.8 | J9: =SUM(J6:J8) -> 155692.8 | ... P9: =SUM(P6:P8) -> 991080
B11: B. VARIABLE CASH OUTFLOWS
B12: Seeds & Transplants | C12: ='Enterprise Budget'!D12*Assumptions!C46 -> 1305.6 | D12: ='Enterprise Budget'!D12*Assumptions!C47 -> 1632 | E12: ='Enterprise Budget'!D12*Assumptions!C48 -> 3264 | F12: ='Enterprise Budget'!D12*Assumptions!C49 -> 3264 | G12: ='Enterprise Budget'!D12*Assumptions!C50 -> 3264 | H12: ='Enterprise Budget'!D12*Assumptions!C51 -> 2937.6 | I12: ='Enterprise Budget'!D12*Assumptions!C52 -> 3264 | J12: ='Enterprise Budget'!D12*Assumptions!C53 -> 3264 | K12: ='Enterprise Budget'!D12*Assumptions!C54 -> 2937.6 | L12: ='Enterprise Budget'!D12*Assumptions!C55 -> 2611.2 | M12: ='Enterprise Budget'!D12*Assumptions!C56 -> 2611.2 | N12: ='Enterprise Budget'!D12*Assumptions!C57 -> 2284.8 | P12: =SUM(C12:N12) -> 32640
B13: Fertilisers & Amendments | C13: ='Enterprise Budget'!D13*Assumptions!C46 -> 1958.4 | D13: ='Enterprise Budget'!D13*Assumptions!C47 -> 2448 | E13: ='Enterprise Budget'!D13*Assumptions!C48 -> 4896 | F13: ='Enterprise Budget'!D13*Assumptions!C49 -> 4896 | G13: ='Enterprise Budget'!D13*Assumptions!C50 -> 4896 | H13: ='Enterprise Budget'!D13*Assumptions!C51 -> 4406.4 | I13: ='Enterprise Budget'!D13*Assumptions!C52 -> 4896 | J13: ='Enterprise Budget'!D13*Assumptions!C53 -> 4896 | K13: ='Enterprise Budget'!D13*Assumptions!C54 -> 4406.4 | L13: ='Enterprise Budget'!D13*Assumptions!C55 -> 3916.8 | M13: ='Enterprise Budget'!D13*Assumptions!C56 -> 3916.8 | N13: ='Enterprise Budget'!D13*Assumptions!C57 -> 3427.2 | P13: =SUM(C13:N13) -> 48960
B14: Pesticides & Fungicides | C14: ='Enterprise Budget'!D14*Assumptions!C46 -> 652.8 | D14: ='Enterprise Budget'!D14*Assumptions!C47 -> 816 | E14: ='Enterprise Budget'!D14*Assumptions!C48 -> 1632 | F14: ='Enterprise Budget'!D14*Assumptions!C49 -> 1632 | G14: ='Enterprise Budget'!D14*Assumptions!C50 -> 1632 | H14: ='Enterprise Budget'!D14*Assumptions!C51 -> 1468.8 | I14: ='Enterprise Budget'!D14*Assumptions!C52 -> 1632 | J14: ='Enterprise Budget'!D14*Assumptions!C53 -> 1632 | K14: ='Enterprise Budget'!D14*Assumptions!C54 -> 1468.8 | L14: ='Enterprise Budget'!D14*Assumptions!C55 -> 1305.6 | M14: ='Enterprise Budget'!D14*Assumptions!C56 -> 1305.6 | N14: ='Enterprise Budget'!D14*Assumptions!C57 -> 1142.4 | P14: =SUM(C14:N14) -> 16320
B15: Irrigation & Water | C15: ='Enterprise Budget'!D15*Assumptions!C46 -> 571.2 | D15: ='Enterprise Budget'!D15*Assumptions!C47 -> 714 | E15: ='Enterprise Budget'!D15*Assumptions!C48 -> 1428 | F15: ='Enterprise Budget'!D15*Assumptions!C49 -> 1428 | G15: ='Enterprise Budget'!D15*Assumptions!C50 -> 1428 | H15: ='Enterprise Budget'!D15*Assumptions!C51 -> 1285.2 | I15: ='Enterprise Budget'!D15*Assumptions!C52 -> 1428 | J15: ='Enterprise Budget'!D15*Assumptions!C53 -> 1428 | K15: ='Enterprise Budget'!D15*Assumptions!C54 -> 1285.2 | L15: ='Enterprise Budget'!D15*Assumptions!C55 -> 1142.4 | M15: ='Enterprise Budget'!D15*Assumptions!C56 -> 1142.4 | N15: ='Enterprise Budget'!D15*Assumptions!C57 -> 999.6 | P15: =SUM(C15:N15) -> 14280
B16: Greenhouse Energy | C16: ='Enterprise Budget'!D16*Assumptions!C46 -> 1550.4 | D16: ='Enterprise Budget'!D16*Assumptions!C47 -> 1938 | E16: ='Enterprise Budget'!D16*Assumptions!C48 -> 3876 | F16: ='Enterprise Budget'!D16*Assumptions!C49 -> 3876 | G16: ='Enterprise Budget'!D16*Assumptions!C50 -> 3876 | H16: ='Enterprise Budget'!D16*Assumptions!C51 -> 3488.4 | I16: ='Enterprise Budget'!D16*Assumptions!C52 -> 3876 | J16: ='Enterprise Budget'!D16*Assumptions!C53 -> 3876 | K16: ='Enterprise Budget'!D16*Assumptions!C54 -> 3488.4 | L16: ='Enterprise Budget'!D16*Assumptions!C55 -> 3100.8 | M16: ='Enterprise Budget'!D16*Assumptions!C56 -> 3100.8 | N16: ='Enterprise Budget'!D16*Assumptions!C57 -> 2713.2 | P16: =SUM(C16:N16) -> 38760
B17: Harvest & Packing Labour | C17: ='Enterprise Budget'!D17*Assumptions!C46 -> 2121.6 | D17: ='Enterprise Budget'!D17*Assumptions!C47 -> 2652 | E17: ='Enterprise Budget'!D17*Assumptions!C48 -> 5304 | F17: ='Enterprise Budget'!D17*Assumptions!C49 -> 5304 | G17: ='Enterprise Budget'!D17*Assumptions!C50 -> 5304 | H17: ='Enterprise Budget'!D17*Assumptions!C51 -> 4773.6 | I17: ='Enterprise Budget'!D17*Assumptions!C52 -> 5304 | J17: ='Enterprise Budget'!D17*Assumptions!C53 -> 5304 | K17: ='Enterprise Budget'!D17*Assumptions!C54 -> 4773.6 | L17: ='Enterprise Budget'!D17*Assumptions!C55 -> 4243.2 | M17: ='Enterprise Budget'!D17*Assumptions!C56 -> 4243.2 | N17: ='Enterprise Budget'!D17*Assumptions!C57 -> 3712.8 | P17: =SUM(C17:N17) -> 53040
B18: Packaging Materials | C18: ='Enterprise Budget'!D18*Assumptions!C46 -> 979.2 | D18: ='Enterprise Budget'!D18*Assumptions!C47 -> 1224 | E18: ='Enterprise Budget'!D18*Assumptions!C48 -> 2448 | F18: ='Enterprise Budget'!D18*Assumptions!C49 -> 2448 | G18: ='Enterprise Budget'!D18*Assumptions!C50 -> 2448 | H18: ='Enterprise Budget'!D18*Assumptions!C51 -> 2203.2 | I18: ='Enterprise Budget'!D18*Assumptions!C52 -> 2448 | J18: ='Enterprise Budget'!D18*Assumptions!C53 -> 2448 | K18: ='Enterprise Budget'!D18*Assumptions!C54 -> 2203.2 | L18: ='Enterprise Budget'!D18*Assumptions!C55 -> 1958.4 | M18: ='Enterprise Budget'!D18*Assumptions!C56 -> 1958.4 | N18: ='Enterprise Budget'!D18*Assumptions!C57 -> 1713.6 | P18: =SUM(C18:N18) -> 24480
B19: Transport to Market | C19: ='Enterprise Budget'!D19*Assumptions!C46 -> 1713.6 | D19: ='Enterprise Budget'!D19*Assumptions!C47 -> 2142 | E19: ='Enterprise Budget'!D19*Assumptions!C48 -> 4284 | F19: ='Enterprise Budget'!D19*Assumptions!C49 -> 4284 | G19: ='Enterprise Budget'!D19*Assumptions!C50 -> 4284 | H19: ='Enterprise Budget'!D19*Assumptions!C51 -> 3855.6 | I19: ='Enterprise Budget'!D19*Assumptions!C52 -> 4284 | J19: ='Enterprise Budget'!D19*Assumptions!C53 -> 4284 | K19: ='Enterprise Budget'!D19*Assumptions!C54 -> 3855.6 | L19: ='Enterprise Budget'!D19*Assumptions!C55 -> 3427.2 | M19: ='Enterprise Budget'!D19*Assumptions!C56 -> 3427.2 | N19: ='Enterprise Budget'!D19*Assumptions!C57 -> 2998.8 | P19: =SUM(C19:N19) -> 42840
B20: Casual Labour – Growing | C20: ='Enterprise Budget'!D20*Assumptions!C46 -> 1428 | D20: ='Enterprise Budget'!D20*Assumptions!C47 -> 1785 | E20: ='Enterprise Budget'!D20*Assumptions!C48 -> 3570 | F20: ='Enterprise Budget'!D20*Assumptions!C49 -> 3570 | G20: ='Enterprise Budget'!D20*Assumptions!C50 -> 3570 | H20: ='Enterprise Budget'!D20*Assumptions!C51 -> 3213 | I20: ='Enterprise Budget'!D20*Assumptions!C52 -> 3570 | J20: ='Enterprise Budget'!D20*Assumptions!C53 -> 3570 | K20: ='Enterprise Budget'!D20*Assumptions!C54 -> 3213 | L20: ='Enterprise Budget'!D20*Assumptions!C55 -> 2856 | M20: ='Enterprise Budget'!D20*Assumptions!C56 -> 2856 | N20: ='Enterprise Budget'!D20*Assumptions!C57 -> 2499 | P20: =SUM(C20:N20) -> 35700
B21: Crop Insurance Premium | C21: ='Enterprise Budget'!D21*Assumptions!C46 -> 734.4 | D21: ='Enterprise Budget'!D21*Assumptions!C47 -> 918 | E21: ='Enterprise Budget'!D21*Assumptions!C48 -> 1836 | F21: ='Enterprise Budget'!D21*Assumptions!C49 -> 1836 | G21: ='Enterprise Budget'!D21*Assumptions!C50 -> 1836 | H21: ='Enterprise Budget'!D21*Assumptions!C51 -> 1652.4 | I21: ='Enterprise Budget'!D21*Assumptions!C52 -> 1836 | J21: ='Enterprise Budget'!D21*Assumptions!C53 -> 1836 | K21: ='Enterprise Budget'!D21*Assumptions!C54 -> 1652.4 | L21: ='Enterprise Budget'!D21*Assumptions!C55 -> 1468.8 | M21: ='Enterprise Budget'!D21*Assumptions!C56 -> 1468.8 | N21: ='Enterprise Budget'!D21*Assumptions!C57 -> 1285.2 | P21: =SUM(C21:N21) -> 18360
B22: TOTAL VARIABLE OUTFLOWS | C22: =SUM(C12:C21) -> 13015.2 | D22: =SUM(D12:D21) -> 16269 | E22: =SUM(E12:E21) -> 32538 | F22: =SUM(F12:F21) -> 32538 | G22: =SUM(G12:G21) -> 32538 | H22: =SUM(H12:H21) -> 29284.2 | I22: =SUM(I12:I21) -> 32538 | J22: =SUM(J12:J21) -> 32538 | ... P22: =SUM(P12:P21) -> 325380
B24: C. FIXED CASH OUTFLOWS (Monthly Equal Spread)
B25: Land / Greenhouse Lease | C25: ='Enterprise Budget'!D26/12 -> 7916.6667 | D25: ='Enterprise Budget'!D26/12 -> 7916.6667 | E25: ='Enterprise Budget'!D26/12 -> 7916.6667 | F25: ='Enterprise Budget'!D26/12 -> 7916.6667 | G25: ='Enterprise Budget'!D26/12 -> 7916.6667 | H25: ='Enterprise Budget'!D26/12 -> 7916.6667 | I25: ='Enterprise Budget'!D26/12 -> 7916.6667 | J25: ='Enterprise Budget'!D26/12 -> 7916.6667 | K25: ='Enterprise Budget'!D26/12 -> 7916.6667 | L25: ='Enterprise Budget'!D26/12 -> 7916.6667 | M25: ='Enterprise Budget'!D26/12 -> 7916.6667 | N25: ='Enterprise Budget'!D26/12 -> 7916.6667 | P25: =SUM(C25:N25) -> 95000
B26: Equipment Depreciation | C26: ='Enterprise Budget'!D27/12 -> 3500 | D26: ='Enterprise Budget'!D27/12 -> 3500 | E26: ='Enterprise Budget'!D27/12 -> 3500 | F26: ='Enterprise Budget'!D27/12 -> 3500 | G26: ='Enterprise Budget'!D27/12 -> 3500 | H26: ='Enterprise Budget'!D27/12 -> 3500 | I26: ='Enterprise Budget'!D27/12 -> 3500 | J26: ='Enterprise Budget'!D27/12 -> 3500 | K26: ='Enterprise Budget'!D27/12 -> 3500 | L26: ='Enterprise Budget'!D27/12 -> 3500 | M26: ='Enterprise Budget'!D27/12 -> 3500 | N26: ='Enterprise Budget'!D27/12 -> 3500 | P26: =SUM(C26:N26) -> 42000
B27: Management Salaries | C27: ='Enterprise Budget'!D28/12 -> 10000 | D27: ='Enterprise Budget'!D28/12 -> 10000 | E27: ='Enterprise Budget'!D28/12 -> 10000 | F27: ='Enterprise Budget'!D28/12 -> 10000 | G27: ='Enterprise Budget'!D28/12 -> 10000 | H27: ='Enterprise Budget'!D28/12 -> 10000 | I27: ='Enterprise Budget'!D28/12 -> 10000 | J27: ='Enterprise Budget'!D28/12 -> 10000 | K27: ='Enterprise Budget'!D28/12 -> 10000 | L27: ='Enterprise Budget'!D28/12 -> 10000 | M27: ='Enterprise Budget'!D28/12 -> 10000 | N27: ='Enterprise Budget'!D28/12 -> 10000 | P27: =SUM(C27:N27) -> 120000
B28: Office & Administration | C28: ='Enterprise Budget'!D29/12 -> 1500 | D28: ='Enterprise Budget'!D29/12 -> 1500 | E28: ='Enterprise Budget'!D29/12 -> 1500 | F28: ='Enterprise Budget'!D29/12 -> 1500 | G28: ='Enterprise Budget'!D29/12 -> 1500 | H28: ='Enterprise Budget'!D29/12 -> 1500 | I28: ='Enterprise Budget'!D29/12 -> 1500 | J28: ='Enterprise Budget'!D29/12 -> 1500 | K28: ='Enterprise Budget'!D29/12 -> 1500 | L28: ='Enterprise Budget'!D29/12 -> 1500 | M28: ='Enterprise Budget'!D29/12 -> 1500 | N28: ='Enterprise Budget'!D29/12 -> 1500 | P28: =SUM(C28:N28) -> 18000
B29: Insurance – Property & Liability | C29: ='Enterprise Budget'!D30/12 -> 1833.3333 | D29: ='Enterprise Budget'!D30/12 -> 1833.3333 | E29: ='Enterprise Budget'!D30/12 -> 1833.3333 | F29: ='Enterprise Budget'!D30/12 -> 1833.3333 | G29: ='Enterprise Budget'!D30/12 -> 1833.3333 | H29: ='Enterprise Budget'!D30/12 -> 1833.3333 | I29: ='Enterprise Budget'!D30/12 -> 1833.3333 | J29: ='Enterprise Budget'!D30/12 -> 1833.3333 | K29: ='Enterprise Budget'!D30/12 -> 1833.3333 | L29: ='Enterprise Budget'!D30/12 -> 1833.3333 | M29: ='Enterprise Budget'!D30/12 -> 1833.3333 | N29: ='Enterprise Budget'!D30/12 -> 1833.3333 | P29: =SUM(C29:N29) -> 22000
B30: Regulatory & Compliance | C30: ='Enterprise Budget'!D31/12 -> 791.66667 | D30: ='Enterprise Budget'!D31/12 -> 791.66667 | E30: ='Enterprise Budget'!D31/12 -> 791.66667 | F30: ='Enterprise Budget'!D31/12 -> 791.66667 | G30: ='Enterprise Budget'!D31/12 -> 791.66667 | H30: ='Enterprise Budget'!D31/12 -> 791.66667 | I30: ='Enterprise Budget'!D31/12 -> 791.66667 | J30: ='Enterprise Budget'!D31/12 -> 791.66667 | K30: ='Enterprise Budget'!D31/12 -> 791.66667 | L30: ='Enterprise Budget'!D31/12 -> 791.66667 | M30: ='Enterprise Budget'!D31/12 -> 791.66667 | N30: ='Enterprise Budget'!D31/12 -> 791.66667 | P30: =SUM(C30:N30) -> 9500
B31: Interest on Operating Loan | C31: ='Enterprise Budget'!D32/12 -> 1166.6667 | D31: ='Enterprise Budget'!D32/12 -> 1166.6667 | E31: ='Enterprise Budget'!D32/12 -> 1166.6667 | F31: ='Enterprise Budget'!D32/12 -> 1166.6667 | G31: ='Enterprise Budget'!D32/12 -> 1166.6667 | H31: ='Enterprise Budget'!D32/12 -> 1166.6667 | I31: ='Enterprise Budget'!D32/12 -> 1166.6667 | J31: ='Enterprise Budget'!D32/12 -> 1166.6667 | K31: ='Enterprise Budget'!D32/12 -> 1166.6667 | L31: ='Enterprise Budget'!D32/12 -> 1166.6667 | M31: ='Enterprise Budget'!D32/12 -> 1166.6667 | N31: ='Enterprise Budget'!D32/12 -> 1166.6667 | P31: =SUM(C31:N31) -> 14000
B32: Repairs & Maintenance | C32: ='Enterprise Budget'!D33/12 -> 2333.3333 | D32: ='Enterprise Budget'!D33/12 -> 2333.3333 | E32: ='Enterprise Budget'!D33/12 -> 2333.3333 | F32: ='Enterprise Budget'!D33/12 -> 2333.3333 | G32: ='Enterprise Budget'!D33/12 -> 2333.3333 | H32: ='Enterprise Budget'!D33/12 -> 2333.3333 | I32: ='Enterprise Budget'!D33/12 -> 2333.3333 | J32: ='Enterprise Budget'!D33/12 -> 2333.3333 | K32: ='Enterprise Budget'!D33/12 -> 2333.3333 | L32: ='Enterprise Budget'!D33/12 -> 2333.3333 | M32: ='Enterprise Budget'!D33/12 -> 2333.3333 | N32: ='Enterprise Budget'!D33/12 -> 2333.3333 | P32: =SUM(C32:N32) -> 28000
B33: TOTAL FIXED OUTFLOWS | C33: =SUM(C25:C32) -> 29041.667 | D33: =SUM(D25:D32) -> 29041.667 | E33: =SUM(E25:E32) -> 29041.667 | F33: =SUM(F25:F32) -> 29041.667 | G33: =SUM(G25:G32) -> 29041.667 | H33: =SUM(H25:H32) -> 29041.667 | I33: =SUM(I25:I32) -> 29041.667 | J33: =SUM(J25:J32) -> 29041.667 | ... P33: =SUM(P25:P32) -> 348500
B35: TOTAL CASH OUTFLOWS | C35: =C22+C33 -> 42056.867 | D35: =D22+D33 -> 45310.667 | E35: =E22+E33 -> 61579.667 | F35: =F22+F33 -> 61579.667 | G35: =G22+G33 -> 61579.667 | H35: =H22+H33 -> 58325.867 | I35: =I22+I33 -> 61579.667 | J35: =J22+J33 -> 61579.667 | ... P35: =P22+P33 -> 673880
B36: NET MONTHLY CASH FLOW | C36: =C9-C35 -> -42056.867 | D36: =D9-D35 -> -45310.667 | E36: =E9-E35 -> -42118.067 | F36: =F9-F35 -> -12925.667 | G36: =G9-G35 -> 35728.333 | H36: =H9-H35 -> 77905.333 | I36: =I9-I35 -> 112113.13 | J36: =J9-J35 -> 94113.133 | ... P36: =P9-P35 -> 317200
B37: Cumulative Cash Flow | C37: =C36 -> -42056.867 | D37: =C37+D36 -> -87367.533 | E37: =D37+E36 -> -129485.6 | F37: =E37+F36 -> -142411.27 | G37: =F37+G36 -> -106682.93 | H37: =G37+H36 -> -28777.6 | I37: =H37+I36 -> 83335.533 | J37: =I37+J36 -> 177448.67 | K37: =J37+K36 -> 255354 | ... N37: =M37+N36 -> 317200 | P37: =N37 -> 317200
B39: Opening Cash Balance (Jan 1) | C39: 15000 | D39: =C40 -> -27056.867 | E39: =D40 -> -72367.533 | F39: =E40 -> -114485.6 | G39: =F40 -> -127411.27 | H39: =G40 -> -91682.933 | I39: =H40 -> -13777.6 | J39: =I40 -> 98335.533 | K39: =J40 -> 192448.67 | ... N39: =M40 -> 345095.07
B40: Closing Cash Balance | C40: =C39+C36 -> -27056.867 | D40: =D39+D36 -> -72367.533 | E40: =E39+E36 -> -114485.6 | F40: =F39+F36 -> -127411.27 | G40: =G39+G36 -> -91682.933 | H40: =H39+H36 -> -13777.6 | I40: =I39+I36 -> 98335.533 | J40: =J39+J36 -> 192448.67 | ... N40: =N39+N36 -> 332200 | P40: =N40 -> 332200

Sheet Break-Even Analysis
B1: BREAK-EVEN ANALYSIS
B2: At what price or yield does the farm break even? Change blue cells to model scenarios.
B4: A. BREAK-EVEN CALCULATIONS
B5: Total Fixed Costs (CAD $) | C5: ='Enterprise Budget'!D34 -> 348500 | E5: Whole-farm annual fixed costs
B6: Total Variable Cost per Tonne (CAD $) | C6: =SUM(Assumptions!C24:C33) -> 319 | E6: Sum of all VC per tonne assumptions
B7: Weighted Average Selling Price (CAD $/tonne) | C7: =(Assumptions!C14*Assumptions!C19)+(Assumptions!C15*Assumptions!C20) -> 954 | E7: Blend of Grade A & B prices
B8: Contribution Margin per Tonne (CAD $) | C8: =C7-C6 -> 635 | E8: Price minus variable cost per tonne
B9: Contribution Margin Ratio | C9: =IFERROR(C8/C7,0) -> 0.66561845 | E9: CM as % of selling price
B10: Break-Even Volume (tonnes) | C10: =IFERROR(C5/C8,0) -> 548.8189 | E10: Fixed costs ÷ contribution margin
B11: Break-Even Hectares | C11: =IFERROR(C10/Assumptions!C12,0) -> 6.4566929 | E11: Break-even tonnes ÷ yield/ha
B12: Break-Even Price (CAD $/tonne) | C12: =IFERROR((C5+C6*Assumptions!C13)/Assumptions!C13,0) -> 660.66667 | E12: Price needed to cover all costs
B13: Margin of Safety (tonnes above break-even) | C13: =Assumptions!C13-C10 -> 471.1811 | E13: How far above break-even is planned output
B14: Margin of Safety % | C14: =IFERROR(C13/Assumptions!C13,0) -> 0.46194226 | E14: Buffer above break-even as % of total output
B16: B. PRICE SENSITIVITY TABLE – Net Farm Income at Different Prices & Yields
B17: Yield → (t/ha) | C17: 65 | D17: 75 | E17: 85 | F17: 95 | G17: 105
B18: Price: CAD $750/t | C18: =(750*Assumptions!C14+750*0.65*Assumptions!C15)*65*Assumptions!C7-C6*65*Assumptions!C7-C5 -> -60582.5 | D18: =(750*Assumptions!C14+750*0.65*Assumptions!C15)*75*Assumptions!C7-C6*75*Assumptions!C7-C5 -> -16287.5 | E18: =(750*Assumptions!C14+750*0.65*Assumptions!C15)*85*Assumptions!C7-C6*85*Assumptions!C7-C5 -> 28007.5 | F18: =(750*Assumptions!C14+750*0.65*Assumptions!C15)*95*Assumptions!C7-C6*95*Assumptions!C7-C5 -> 72302.5 | G18: =(750*Assumptions!C14+750*0.65*Assumptions!C15)*105*Assumptions!C7-C6*105*Assumptions!C7-C5 -> 116597.5
B19: Price: CAD $850/t | C19: =(850*Assumptions!C14+850*0.65*Assumptions!C15)*65*Assumptions!C7-C6*65*Assumptions!C7-C5 -> 10982.5 | D19: =(850*Assumptions!C14+850*0.65*Assumptions!C15)*75*Assumptions!C7-C6*75*Assumptions!C7-C5 -> 66287.5 | E19: =(850*Assumptions!C14+850*0.65*Assumptions!C15)*85*Assumptions!C7-C6*85*Assumptions!C7-C5 -> 121592.5 | F19: =(850*Assumptions!C14+850*0.65*Assumptions!C15)*95*Assumptions!C7-C6*95*Assumptions!C7-C5 -> 176897.5 | G19: =(850*Assumptions!C14+850*0.65*Assumptions!C15)*105*Assumptions!C7-C6*105*Assumptions!C7-C5 -> 232202.5
B20: Price: CAD $950/t | C20: =(950*Assumptions!C14+950*0.65*Assumptions!C15)*65*Assumptions!C7-C6*65*Assumptions!C7-C5 -> 82547.5 | D20: =(950*Assumptions!C14+950*0.65*Assumptions!C15)*75*Assumptions!C7-C6*75*Assumptions!C7-C5 -> 148862.5 | E20: =(950*Assumptions!C14+950*0.65*Assumptions!C15)*85*Assumptions!C7-C6*85*Assumptions!C7-C5 -> 215177.5 | F20: =(950*Assumptions!C14+950*0.65*Assumptions!C15)*95*Assumptions!C7-C6*95*Assumptions!C7-C5 -> 281492.5 | G20: =(950*Assumptions!C14+950*0.65*Assumptions!C15)*105*Assumptions!C7-C6*105*Assumptions!C7-C5 -> 347807.5
B21: Price: CAD $1050/t | C21: =(1050*Assumptions!C14+1050*0.65*Assumptions!C15)*65*Assumptions!C7-C6*65*Assumptions!C7-C5 -> 154112.5 | D21: =(1050*Assumptions!C14+1050*0.65*Assumptions!C15)*75*Assumptions!C7-C6*75*Assumptions!C7-C5 -> 231437.5 | E21: =(1050*Assumptions!C14+1050*0.65*Assumptions!C15)*85*Assumptions!C7-C6*85*Assumptions!C7-C5 -> 308762.5 | F21: =(1050*Assumptions!C14+1050*0.65*Assumptions!C15)*95*Assumptions!C7-C6*95*Assumptions!C7-C5 -> 386087.5 | G21: =(1050*Assumptions!C14+1050*0.65*Assumptions!C15)*105*Assumptions!C7-C6*105*Assumptions!C7-C5 -> 463412.5
B22: Price: CAD $1150/t | C22: =(1150*Assumptions!C14+1150*0.65*Assumptions!C15)*65*Assumptions!C7-C6*65*Assumptions!C7-C5 -> 225677.5 | D22: =(1150*Assumptions!C14+1150*0.65*Assumptions!C15)*75*Assumptions!C7-C6*75*Assumptions!C7-C5 -> 314012.5 | E22: =(1150*Assumptions!C14+1150*0.65*Assumptions!C15)*85*Assumptions!C7-C6*85*Assumptions!C7-C5 -> 402347.5 | F22: =(1150*Assumptions!C14+1150*0.65*Assumptions!C15)*95*Assumptions!C7-C6*95*Assumptions!C7-C5 -> 490682.5 | G22: =(1150*Assumptions!C14+1150*0.65*Assumptions!C15)*105*Assumptions!C7-C6*105*Assumptions!C7-C5 -> 579017.5
B24: HOW TO READ THIS TABLE
B25: • Each cell shows Net Farm Income at that combination of price and yield.
B26: • Negative values (in brackets) mean the farm makes a loss at that scenario.
B27: • The break-even row/column is where Net Farm Income = 0.
B28: • Use this to advise the farm manager on minimum price or yield targets.
B29: • To add your own scenario: change the price or yield values in column B / row 17.

Sheet Partial Budget
B1: PARTIAL BUDGET – GREENHOUSE EXPANSION DECISION
B2: Should the farm add 3 more greenhouse hectares? This partial budget analyses the net change.
B4: PROPOSED CHANGE: Add 3 ha of greenhouse capacity
B5: A. BENEFITS (Increases in Revenue + Decreases in Cost)
B6: Additional Grade A Revenue (3 ha × yield × Grade A price) | C6: =3*Assumptions!C12*Assumptions!C14*Assumptions!C19 -> 219555 | D6: New sales from expanded area
B7: Additional Grade B Revenue (3 ha × yield × Grade B price) | C7: =3*Assumptions!C12*Assumptions!C15*Assumptions!C20 -> 23715 | D7: Secondary market revenue
B8: Bulk input discount (estimated 5% on variable costs) | C8: =0.05*3*Assumptions!C12*SUM(Assumptions!C24:C33) -> 4067.25 | D8: Volume purchasing saving
B9: TOTAL BENEFITS | C9: =SUM(C6:C8) -> 247337.25
B11: B. COSTS (Increases in Cost + Decreases in Revenue)
B12: Additional Variable Costs (3 ha × yield × VC/tonne) | C12: =3*Assumptions!C12*SUM(Assumptions!C24:C33) -> 81345 | D12: Direct production cost increase
B13: Additional Lease Cost (3 ha × CAD $7,500/ha) | C13: =3*7500 -> 22500 | D13: New greenhouse lease annualised
B14: Additional Labour – Supervision (1 FTE) | C14: =55000 -> 55000 | D14: Greenhouse supervisor @ CAD $55k/yr
B15: Loan Repayment – Capital Investment (CAD $300k @ 7%, 10 yr) | C15: =300000*(0.07/(1-(1+0.07)^-10)) -> 42713.251 | D15: Annual loan payment on expansion capital
B16: Depreciation – New Equipment (CAD $80k, 10 yr) | C16: =80000/10 -> 8000 | D16: Straight-line depreciation on expansion assets
B17: TOTAL COSTS | C17: =SUM(C12:C16) -> 209558.25
B19: NET CHANGE IN FARM INCOME (Benefits – Costs) | C19: =C9-C17 -> 37778.999
B21: RECOMMENDATION
B22: =IF(C19>0,"✓ PROCEED – The expansion generates a positive net change of "&TEXT(C19,"CAD $#,##0")&" per year. The investment is financially justified.","✗ DO NOT PROCEED – The expansion reduces income by "&TEXT(ABS(C19),"CAD $#,##0")&" per year. Re-evaluate costs or pricing strategy.") -> #VALUE!

Sheet 5-Year Projection
B1: 5-YEAR FINANCIAL PROJECTION – MAPLE LEAF FRESH FARMS
B3: GROWTH ASSUMPTIONS (Blue = editable)
B4: Annual revenue growth rate | C4: 0.05 | H4: Price improvement + volume growth
B5: Annual variable cost inflation | C5: 0.04 | H5: Labour & input cost inflation
B6: Annual fixed cost inflation | C6: 0.03 | H6: Lease & salary escalation
B7: Year 1 baseline – Total Revenue | C7: ='Enterprise Budget'!D9 -> 991080 | H7: From Enterprise Budget
B8: Year 1 baseline – Variable Costs | C8: ='Enterprise Budget'!D22 -> 325380 | H8: From Enterprise Budget
B9: Year 1 baseline – Fixed Costs | C9: ='Enterprise Budget'!D34 -> 348500 | H9: From Enterprise Budget
B11: Metric | C11: Year 1 (2025) | D11: Year 2 (2026) | E11: Year 3 (2027) | F11: Year 4 (2028) | G11: Year 5 (2029) | H11: 5-Yr CAGR
B12: Total Revenue | C12: =$C$7 -> 991080 | D12: =C12*(1+$C$4) -> 1040634 | E12: =D12*(1+$C$4) -> 1092665.7 | F12: =E12*(1+$C$4) -> 1147299 | G12: =F12*(1+$C$4) -> 1204663.9 | H12: =IFERROR((G12/C12)^(1/4)-1,0) -> 0.05
B13: Total Variable Costs | C13: =$C$8 -> 325380 | D13: =C13*(1+$C$5) -> 338395.2 | E13: =D13*(1+$C$5) -> 351931.01 | F13: =E13*(1+$C$5) -> 366008.25 | G13: =F13*(1+$C$5) -> 380648.58
B14: Gross Margin | C14: =C12-C13 -> 665700 | D14: =D12-D13 -> 702238.8 | E14: =E12-E13 -> 740734.69 | F14: =F12-F13 -> 781290.74 | G14: =G12-G13 -> 824015.36 | H14: =IFERROR((G14/C14)^(1/4)-1,0) -> 0.054785588
B15: Gross Margin % | C15: =IFERROR(C14/C12,0) -> 0.67169149 | D15: =IFERROR(D14/D12,0) -> 0.67481824 | E15: =IFERROR(E14/E12,0) -> 0.6779152 | F15: =IFERROR(F14/F12,0) -> 0.68098268 | G15: =IFERROR(G14/G12,0) -> 0.68402094
B16: Total Fixed Costs | C16: =$C$9 -> 348500 | D16: =C16*(1+$C$6) -> 358955 | E16: =D16*(1+$C$6) -> 369723.65 | F16: =E16*(1+$C$6) -> 380815.36 | G16: =F16*(1+$C$6) -> 392239.82
B17: Net Farm Income | C17: =C14-C16 -> 317200 | D17: =D14-D16 -> 343283.8 | E17: =E14-E16 -> 371011.04 | F17: =F14-F16 -> 400475.38 | G17: =G14-G16 -> 431775.54 | H17: =IFERROR((G17/C17)^(1/4)-1,0) -> 0.080142895
B18: Net Farm Income % | C18: =IFERROR(C17/C12,0) -> 0.32005489 | D18: =IFERROR(D17/D12,0) -> 0.32987948 | E18: =IFERROR(E17/E12,0) -> 0.33954671 | F18: =IFERROR(F17/F12,0) -> 0.3490593 | G18: =IFERROR(G17/G12,0) -> 0.35841991
